Workbook

Sheet Summary
A1: Resale Stack — Week 2 evaluation results
A2: 150 hand-labeled listings · 3 Claude models · 2 prompt versions · 2 label versions. 'Agreement' = match with my labels, not objective accuracy. Original labels are the headline.
A4: Headline: condition-tier agreement
A5: Model | B5: v1 · original | C5: v1 · corrected | D5: v2 · original | E5: v2 · corrected | F5: v1 gap (pts) | G5: v2 gap (pts) | H5: Price per M tokens (in / out)
A6: Sonnet 5 | B6: =('V1 Matrices'!B7+'V1 Matrices'!C8+'V1 Matrices'!D9+'V1 Matrices'!E10+'V1 Matrices'!F11+'V1 Matrices'!G12)/150 -> 0.49333333 | C6: =('V1 Corrected'!B7+'V1 Corrected'!C8+'V1 Corrected'!D9+'V1 Corrected'!E10+'V1 Corrected'!F11+'V1 Corrected'!G12)/150 -> 0.57333333 | D6: =('V2 Matrices'!B7+'V2 Matrices'!C8+'V2 Matrices'!D9+'V2 Matrices'!E10+'V2 Matrices'!F11+'V2 Matrices'!G12)/150 -> 0.7 | E6: =('V2 Corrected'!B7+'V2 Corrected'!C8+'V2 Corrected'!D9+'V2 Corrected'!E10+'V2 Corrected'!F11+'V2 Corrected'!G12)/150 -> 0.82 | F6: =(C6-B6)*100 -> 8 | G6: =(E6-D6)*100 -> 12 | H6: $2 / $10
A7: Haiku 4.5 | B7: =('V1 Matrices'!B18+'V1 Matrices'!C19+'V1 Matrices'!D20+'V1 Matrices'!E21+'V1 Matrices'!F22+'V1 Matrices'!G23)/150 -> 0.58666667 | C7: =('V1 Corrected'!B18+'V1 Corrected'!C19+'V1 Corrected'!D20+'V1 Corrected'!E21+'V1 Corrected'!F22+'V1 Corrected'!G23)/150 -> 0.65333333 | D7: =('V2 Matrices'!B18+'V2 Matrices'!C19+'V2 Matrices'!D20+'V2 Matrices'!E21+'V2 Matrices'!F22+'V2 Matrices'!G23)/150 -> 0.72666667 | E7: =('V2 Corrected'!B18+'V2 Corrected'!C19+'V2 Corrected'!D20+'V2 Corrected'!E21+'V2 Corrected'!F22+'V2 Corrected'!G23)/150 -> 0.81333333 | F7: =(C7-B7)*100 -> 6.6666667 | G7: =(E7-D7)*100 -> 8.6666667 | H7: $1 / $5
A8: Opus 5 | B8: =('V1 Matrices'!B29+'V1 Matrices'!C30+'V1 Matrices'!D31+'V1 Matrices'!E32+'V1 Matrices'!F33+'V1 Matrices'!G34)/150 -> 0.50666667 | C8: =('V1 Corrected'!B29+'V1 Corrected'!C30+'V1 Corrected'!D31+'V1 Corrected'!E32+'V1 Corrected'!F33+'V1 Corrected'!G34)/150 -> 0.62 | D8: =('V2 Matrices'!B29+'V2 Matrices'!C30+'V2 Matrices'!D31+'V2 Matrices'!E32+'V2 Matrices'!F33+'V2 Matrices'!G34)/150 -> 0.75333333 | E8: =('V2 Corrected'!B29+'V2 Corrected'!C30+'V2 Corrected'!D31+'V2 Corrected'!E32+'V2 Corrected'!F33+'V2 Corrected'!G34)/150 -> 0.86666667 | F8: =(C8-B8)*100 -> 11.333333 | G8: =(E8-D8)*100 -> 11.333333 | H8: $5 / $25
A9: Yellow = corrected labels. Prices are published API list prices at time of run (verify before quoting). Gap = how much of apparent disagreement was my own label noise.
A11: Agreement by field (original labels)
A12: Model | B12: Prompt | C12: Brand | D12: Subcategory | E12: Tier | F12: Brand % | G12: Subcategory % | H12: Tier %
A13: Sonnet 5 | B13: v1 | C13: 137 | D13: 51 | E13: ='V1 Matrices'!B7+'V1 Matrices'!C8+'V1 Matrices'!D9+'V1 Matrices'!E10+'V1 Matrices'!F11+'V1 Matrices'!G12 -> 74 | F13: =C13/150 -> 0.91333333 | G13: =D13/150 -> 0.34 | H13: =E13/150 -> 0.49333333
A14: Sonnet 5 | B14: v2 | C14: 136 | D14: 49 | E14: ='V2 Matrices'!B7+'V2 Matrices'!C8+'V2 Matrices'!D9+'V2 Matrices'!E10+'V2 Matrices'!F11+'V2 Matrices'!G12 -> 105 | F14: =C14/150 -> 0.90666667 | G14: =D14/150 -> 0.32666667 | H14: =E14/150 -> 0.7
A15: Haiku 4.5 | B15: v1 | C15: 136 | D15: 48 | E15: ='V1 Matrices'!B18+'V1 Matrices'!C19+'V1 Matrices'!D20+'V1 Matrices'!E21+'V1 Matrices'!F22+'V1 Matrices'!G23 -> 88 | F15: =C15/150 -> 0.90666667 | G15: =D15/150 -> 0.32 | H15: =E15/150 -> 0.58666667
A16: Haiku 4.5 | B16: v2 | C16: 136 | D16: 48 | E16: ='V2 Matrices'!B18+'V2 Matrices'!C19+'V2 Matrices'!D20+'V2 Matrices'!E21+'V2 Matrices'!F22+'V2 Matrices'!G23 -> 109 | F16: =C16/150 -> 0.90666667 | G16: =D16/150 -> 0.32 | H16: =E16/150 -> 0.72666667
A17: Opus 5 | B17: v1 | C17: 136 | D17: 30 | E17: ='V1 Matrices'!B29+'V1 Matrices'!C30+'V1 Matrices'!D31+'V1 Matrices'!E32+'V1 Matrices'!F33+'V1 Matrices'!G34 -> 76 | F17: =C17/150 -> 0.90666667 | G17: =D17/150 -> 0.2 | H17: =E17/150 -> 0.50666667
A18: Opus 5 | B18: v2 | C18: 134 | D18: 33 | E18: ='V2 Matrices'!B29+'V2 Matrices'!C30+'V2 Matrices'!D31+'V2 Matrices'!E32+'V2 Matrices'!F33+'V2 Matrices'!G34 -> 113 | F18: =C18/150 -> 0.89333333 | G18: =D18/150 -> 0.22 | H18: =E18/150 -> 0.75333333
A19: Brand and subcategory instructions never changed, so they act as a control. Subcategory is low because it was free text with no fixed vocabulary.
A21: Condition tier detail
A22: Metric | B22: Sonnet v1 | C22: Sonnet v1 corr | D22: Sonnet v2 | E22: Sonnet v2 corr | F22: Haiku v1 | G22: Haiku v1 corr | H22: Haiku v2 | I22: Haiku v2 corr | J22: Opus v1 | K22: Opus v1 corr | L22: Opus v2 | M22: Opus v2 corr
A23: Tier agreement (count) | B23: ='V1 Matrices'!B7+'V1 Matrices'!C8+'V1 Matrices'!D9+'V1 Matrices'!E10+'V1 Matrices'!F11+'V1 Matrices'!G12 -> 74 | C23: ='V1 Corrected'!B7+'V1 Corrected'!C8+'V1 Corrected'!D9+'V1 Corrected'!E10+'V1 Corrected'!F11+'V1 Corrected'!G12 -> 86 | D23: ='V2 Matrices'!B7+'V2 Matrices'!C8+'V2 Matrices'!D9+'V2 Matrices'!E10+'V2 Matrices'!F11+'V2 Matrices'!G12 -> 105 | E23: ='V2 Corrected'!B7+'V2 Corrected'!C8+'V2 Corrected'!D9+'V2 Corrected'!E10+'V2 Corrected'!F11+'V2 Corrected'!G12 -> 123 | F23: ='V1 Matrices'!B18+'V1 Matrices'!C19+'V1 Matrices'!D20+'V1 Matrices'!E21+'V1 Matrices'!F22+'V1 Matrices'!G23 -> 88 | G23: ='V1 Corrected'!B18+'V1 Corrected'!C19+'V1 Corrected'!D20+'V1 Corrected'!E21+'V1 Corrected'!F22+'V1 Corrected'!G23 -> 98 | H23: ='V2 Matrices'!B18+'V2 Matrices'!C19+'V2 Matrices'!D20+'V2 Matrices'!E21+'V2 Matrices'!F22+'V2 Matrices'!G23 -> 109 | I23: ='V2 Corrected'!B18+'V2 Corrected'!C19+'V2 Corrected'!D20+'V2 Corrected'!E21+'V2 Corrected'!F22+'V2 Corrected'!G23 -> 122 | J23: ='V1 Matrices'!B29+'V1 Matrices'!C30+'V1 Matrices'!D31+'V1 Matrices'!E32+'V1 Matrices'!F33+'V1 Matrices'!G34 -> 76 | K23: ='V1 Corrected'!B29+'V1 Corrected'!C30+'V1 Corrected'!D31+'V1 Corrected'!E32+'V1 Corrected'!F33+'V1 Corrected'!G34 -> 93 | L23: ='V2 Matrices'!B29+'V2 Matrices'!C30+'V2 Matrices'!D31+'V2 Matrices'!E32+'V2 Matrices'!F33+'V2 Matrices'!G34 -> 113 | M23: ='V2 Corrected'!B29+'V2 Corrected'!C30+'V2 Corrected'!D31+'V2 Corrected'!E32+'V2 Corrected'!F33+'V2 Corrected'!G34 -> 130
A24: Tier agreement % | B24: =B23/150 -> 0.49333333 | C24: =C23/150 -> 0.57333333 | D24: =D23/150 -> 0.7 | E24: =E23/150 -> 0.82 | F24: =F23/150 -> 0.58666667 | G24: =G23/150 -> 0.65333333 | H24: =H23/150 -> 0.72666667 | I24: =I23/150 -> 0.81333333 | ... M24: =M23/150 -> 0.86666667
A25: Model declined, I graded | B25: =SUM('V1 Matrices'!G7:G11) -> 29 | C25: =SUM('V1 Corrected'!G7:G11) -> 29 | D25: =SUM('V2 Matrices'!G7:G11) -> 1 | E25: =SUM('V2 Corrected'!G7:G11) -> 0 | F25: =SUM('V1 Matrices'!G18:G22) -> 30 | G25: =SUM('V1 Corrected'!G18:G22) -> 29 | H25: =SUM('V2 Matrices'!G18:G22) -> 6 | I25: =SUM('V2 Corrected'!G18:G22) -> 5 | J25: =SUM('V1 Matrices'!G29:G33) -> 38 | K25: =SUM('V1 Corrected'!G29:G33) -> 37 | L25: =SUM('V2 Matrices'!G29:G33) -> 2 | M25: =SUM('V2 Corrected'!G29:G33) -> 0
A26: I declined, model graded | B26: =SUM('V1 Matrices'!B12:F12) -> 6 | C26: =SUM('V1 Corrected'!B12:F12) -> 2 | D26: =SUM('V2 Matrices'!B12:F12) -> 9 | E26: =SUM('V2 Corrected'!B12:F12) -> 4 | F26: =SUM('V1 Matrices'!B23:F23) -> 6 | G26: =SUM('V1 Corrected'!B23:F23) -> 1 | H26: =SUM('V2 Matrices'!B23:F23) -> 8 | I26: =SUM('V2 Corrected'!B23:F23) -> 3 | J26: =SUM('V1 Matrices'!B34:F34) -> 5 | K26: =SUM('V1 Corrected'!B34:F34) -> 0 | L26: =SUM('V2 Matrices'!B34:F34) -> 6 | M26: =SUM('V2 Corrected'!B34:F34) -> 0
A27: Both declined | B27: ='V1 Matrices'!G12 -> 27 | C27: ='V1 Corrected'!G12 -> 27 | D27: ='V2 Matrices'!G12 -> 24 | E27: ='V2 Corrected'!G12 -> 25 | F27: ='V1 Matrices'!G23 -> 27 | G27: ='V1 Corrected'!G23 -> 28 | H27: ='V2 Matrices'!G23 -> 25 | I27: ='V2 Corrected'!G23 -> 26 | J27: ='V1 Matrices'!G34 -> 28 | K27: ='V1 Corrected'!G34 -> 29 | L27: ='V2 Matrices'!G34 -> 27 | M27: ='V2 Corrected'!G34 -> 29
A28: Both graded | B28: =150-B25-B26-B27 -> 88 | C28: =150-C25-C26-C27 -> 92 | D28: =150-D25-D26-D27 -> 116 | E28: =150-E25-E26-E27 -> 121 | F28: =150-F25-F26-F27 -> 87 | G28: =150-G25-G26-G27 -> 92 | H28: =150-H25-H26-H27 -> 111 | I28: =150-I25-I26-I27 -> 116 | ... M28: =150-M25-M26-M27 -> 121
A29: Agreement where both graded | B29: =IFERROR((B23-B27)/B28,0) -> 0.53409091 | C29: =IFERROR((C23-C27)/C28,0) -> 0.64130435 | D29: =IFERROR((D23-D27)/D28,0) -> 0.69827586 | E29: =IFERROR((E23-E27)/E28,0) -> 0.80991736 | F29: =IFERROR((F23-F27)/F28,0) -> 0.70114943 | G29: =IFERROR((G23-G27)/G28,0) -> 0.76086957 | H29: =IFERROR((H23-H27)/H28,0) -> 0.75675676 | I29: =IFERROR((I23-I27)/I28,0) -> 0.82758621 | ... M29: =IFERROR((M23-M27)/M28,0) -> 0.83471074
A30: Model more generous | B30: =SUM('V1 Matrices'!B8,'V1 Matrices'!B9:C9,'V1 Matrices'!B10:D10,'V1 Matrices'!B11:E11) -> 27 | C30: =SUM('V1 Corrected'!B8,'V1 Corrected'!B9:C9,'V1 Corrected'!B10:D10,'V1 Corrected'!B11:E11) -> 23 | D30: =SUM('V2 Matrices'!B8,'V2 Matrices'!B9:C9,'V2 Matrices'!B10:D10,'V2 Matrices'!B11:E11) -> 20 | E30: =SUM('V2 Corrected'!B8,'V2 Corrected'!B9:C9,'V2 Corrected'!B10:D10,'V2 Corrected'!B11:E11) -> 15 | F30: =SUM('V1 Matrices'!B19,'V1 Matrices'!B20:C20,'V1 Matrices'!B21:D21,'V1 Matrices'!B22:E22) -> 19 | G30: =SUM('V1 Corrected'!B19,'V1 Corrected'!B20:C20,'V1 Corrected'!B21:D21,'V1 Corrected'!B22:E22) -> 20 | H30: =SUM('V2 Matrices'!B19,'V2 Matrices'!B20:C20,'V2 Matrices'!B21:D21,'V2 Matrices'!B22:E22) -> 19 | I30: =SUM('V2 Corrected'!B19,'V2 Corrected'!B20:C20,'V2 Corrected'!B21:D21,'V2 Corrected'!B22:E22) -> 18 | J30: =SUM('V1 Matrices'!B30,'V1 Matrices'!B31:C31,'V1 Matrices'!B32:D32,'V1 Matrices'!B33:E33) -> 17 | K30: =SUM('V1 Corrected'!B30,'V1 Corrected'!B31:C31,'V1 Corrected'!B32:D32,'V1 Corrected'!B33:E33) -> 13 | L30: =SUM('V2 Matrices'!B30,'V2 Matrices'!B31:C31,'V2 Matrices'!B32:D32,'V2 Matrices'!B33:E33) -> 13 | M30: =SUM('V2 Corrected'!B30,'V2 Corrected'!B31:C31,'V2 Corrected'!B32:D32,'V2 Corrected'!B33:E33) -> 10
A31: Model stricter | B31: =SUM('V1 Matrices'!C7:F7,'V1 Matrices'!D8:F8,'V1 Matrices'!E9:F9,'V1 Matrices'!F10) -> 14 | C31: =SUM('V1 Corrected'!C7:F7,'V1 Corrected'!D8:F8,'V1 Corrected'!E9:F9,'V1 Corrected'!F10) -> 10 | D31: =SUM('V2 Matrices'!C7:F7,'V2 Matrices'!D8:F8,'V2 Matrices'!E9:F9,'V2 Matrices'!F10) -> 15 | E31: =SUM('V2 Corrected'!C7:F7,'V2 Corrected'!D8:F8,'V2 Corrected'!E9:F9,'V2 Corrected'!F10) -> 8 | F31: =SUM('V1 Matrices'!C18:F18,'V1 Matrices'!D19:F19,'V1 Matrices'!E20:F20,'V1 Matrices'!F21) -> 7 | G31: =SUM('V1 Corrected'!C18:F18,'V1 Corrected'!D19:F19,'V1 Corrected'!E20:F20,'V1 Corrected'!F21) -> 2 | H31: =SUM('V2 Matrices'!C18:F18,'V2 Matrices'!D19:F19,'V2 Matrices'!E20:F20,'V2 Matrices'!F21) -> 8 | I31: =SUM('V2 Corrected'!C18:F18,'V2 Corrected'!D19:F19,'V2 Corrected'!E20:F20,'V2 Corrected'!F21) -> 2 | J31: =SUM('V1 Matrices'!C29:F29,'V1 Matrices'!D30:F30,'V1 Matrices'!E31:F31,'V1 Matrices'!F32) -> 14 | K31: =SUM('V1 Corrected'!C29:F29,'V1 Corrected'!D30:F30,'V1 Corrected'!E31:F31,'V1 Corrected'!F32) -> 7 | L31: =SUM('V2 Matrices'!C29:F29,'V2 Matrices'!D30:F30,'V2 Matrices'!E31:F31,'V2 Matrices'!F32) -> 16 | M31: =SUM('V2 Corrected'!C29:F29,'V2 Corrected'!D30:F30,'V2 Corrected'!E31:F31,'V2 Corrected'!F32) -> 10
A32: Generous share | B32: =IFERROR(B30/(B30+B31),0) -> 0.65853659 | C32: =IFERROR(C30/(C30+C31),0) -> 0.6969697 | D32: =IFERROR(D30/(D30+D31),0) -> 0.57142857 | E32: =IFERROR(E30/(E30+E31),0) -> 0.65217391 | F32: =IFERROR(F30/(F30+F31),0) -> 0.73076923 | G32: =IFERROR(G30/(G30+G31),0) -> 0.90909091 | H32: =IFERROR(H30/(H30+H31),0) -> 0.7037037 | I32: =IFERROR(I30/(I30+I31),0) -> 0.9 | ... M32: =IFERROR(M30/(M30+M31),0) -> 0.5
A33: One-tier misses | B33: ='V1 Matrices'!C7+'V1 Matrices'!B8+'V1 Matrices'!D8+'V1 Matrices'!C9+'V1 Matrices'!E9+'V1 Matrices'!D10+'V1 Matrices'!F10+'V1 Matrices'!E11 -> 38 | C33: ='V1 Corrected'!C7+'V1 Corrected'!B8+'V1 Corrected'!D8+'V1 Corrected'!C9+'V1 Corrected'!E9+'V1 Corrected'!D10+'V1 Corrected'!F10+'V1 Corrected'!E11 -> 29 | D33: ='V2 Matrices'!C7+'V2 Matrices'!B8+'V2 Matrices'!D8+'V2 Matrices'!C9+'V2 Matrices'!E9+'V2 Matrices'!D10+'V2 Matrices'!F10+'V2 Matrices'!E11 -> 34 | E33: ='V2 Corrected'!C7+'V2 Corrected'!B8+'V2 Corrected'!D8+'V2 Corrected'!C9+'V2 Corrected'!E9+'V2 Corrected'!D10+'V2 Corrected'!F10+'V2 Corrected'!E11 -> 22 | F33: ='V1 Matrices'!C18+'V1 Matrices'!B19+'V1 Matrices'!D19+'V1 Matrices'!C20+'V1 Matrices'!E20+'V1 Matrices'!D21+'V1 Matrices'!F21+'V1 Matrices'!E22 -> 26 | G33: ='V1 Corrected'!C18+'V1 Corrected'!B19+'V1 Corrected'!D19+'V1 Corrected'!C20+'V1 Corrected'!E20+'V1 Corrected'!D21+'V1 Corrected'!F21+'V1 Corrected'!E22 -> 20 | H33: ='V2 Matrices'!C18+'V2 Matrices'!B19+'V2 Matrices'!D19+'V2 Matrices'!C20+'V2 Matrices'!E20+'V2 Matrices'!D21+'V2 Matrices'!F21+'V2 Matrices'!E22 -> 27 | I33: ='V2 Corrected'!C18+'V2 Corrected'!B19+'V2 Corrected'!D19+'V2 Corrected'!C20+'V2 Corrected'!E20+'V2 Corrected'!D21+'V2 Corrected'!F21+'V2 Corrected'!E22 -> 18 | J33: ='V1 Matrices'!C29+'V1 Matrices'!B30+'V1 Matrices'!D30+'V1 Matrices'!C31+'V1 Matrices'!E31+'V1 Matrices'!D32+'V1 Matrices'!F32+'V1 Matrices'!E33 -> 28 | K33: ='V1 Corrected'!C29+'V1 Corrected'!B30+'V1 Corrected'!D30+'V1 Corrected'!C31+'V1 Corrected'!E31+'V1 Corrected'!D32+'V1 Corrected'!F32+'V1 Corrected'!E33 -> 16 | L33: ='V2 Matrices'!C29+'V2 Matrices'!B30+'V2 Matrices'!D30+'V2 Matrices'!C31+'V2 Matrices'!E31+'V2 Matrices'!D32+'V2 Matrices'!F32+'V2 Matrices'!E33 -> 27 | M33: ='V2 Corrected'!C29+'V2 Corrected'!B30+'V2 Corrected'!D30+'V2 Corrected'!C31+'V2 Corrected'!E31+'V2 Corrected'!D32+'V2 Corrected'!F32+'V2 Corrected'!E33 -> 18
A34: Two-plus-tier misses | B34: =B30+B31-B33 -> 3 | C34: =C30+C31-C33 -> 4 | D34: =D30+D31-D33 -> 1 | E34: =E30+E31-E33 -> 1 | F34: =F30+F31-F33 -> 0 | G34: =G30+G31-G33 -> 2 | H34: =H30+H31-H33 -> 0 | I34: =I30+I31-I33 -> 2 | ... M34: =M30+M31-M33 -> 2
A35: Excellent → Pristine | B35: ='V1 Matrices'!B8 -> 8 | C35: ='V1 Corrected'!B8 -> 4 | D35: ='V2 Matrices'!B8 -> 10 | E35: ='V2 Corrected'!B8 -> 5 | F35: ='V1 Matrices'!B19 -> 9 | G35: ='V1 Corrected'!B19 -> 8 | H35: ='V2 Matrices'!B19 -> 7 | I35: ='V2 Corrected'!B19 -> 6 | J35: ='V1 Matrices'!B30 -> 4 | K35: ='V1 Corrected'!B30 -> 0 | L35: ='V2 Matrices'!B30 -> 3 | M35: ='V2 Corrected'!B30 -> 0
A37: Blue-shaded = v2 original; yellow = corrected labels.
A39: 'Claim without evidence' slice
A40: Model | B40: Prompt | C40: Labels | D40: Tagged rows | E40: Tagged agree | F40: Tagged: model declined | G40: Untagged rows | H40: Untagged agree | I40: Untagged: model declined | J40: Tagged % | K40: Untagged % | L40: Check vs tier agreement
A41: Sonnet 5 | B41: v1 | C41: original | D41: 37 | E41: 8 | F41: 19 | G41: 113 | H41: 66 | I41: 10 | J41: =E41/D41 -> 0.21621622 | K41: =H41/G41 -> 0.5840708 | L41: =IF(E41+H41='V1 Matrices'!B7+'V1 Matrices'!C8+'V1 Matrices'!D9+'V1 Matrices'!E10+'V1 Matrices'!F11+'V1 Matrices'!G12,"OK","MISMATCH") -> OK
A42: Sonnet 5 | B42: v1 | C42: corrected | D42: 39 | E42: 10 | F42: 20 | G42: 111 | H42: 76 | I42: 9 | J42: =E42/D42 -> 0.25641026 | K42: =H42/G42 -> 0.68468468 | L42: =IF(E42+H42='V1 Corrected'!B7+'V1 Corrected'!C8+'V1 Corrected'!D9+'V1 Corrected'!E10+'V1 Corrected'!F11+'V1 Corrected'!G12,"OK","MISMATCH") -> OK
A43: Sonnet 5 | B43: v2 | C43: original | D43: 37 | E43: 25 | F43: 0 | G43: 113 | H43: 80 | I43: 1 | J43: =E43/D43 -> 0.67567568 | K43: =H43/G43 -> 0.7079646 | L43: =IF(E43+H43='V2 Matrices'!B7+'V2 Matrices'!C8+'V2 Matrices'!D9+'V2 Matrices'!E10+'V2 Matrices'!F11+'V2 Matrices'!G12,"OK","MISMATCH") -> OK
A44: Sonnet 5 | B44: v2 | C44: corrected | D44: 39 | E44: 31 | F44: 0 | G44: 111 | H44: 92 | I44: 0 | J44: =E44/D44 -> 0.79487179 | K44: =H44/G44 -> 0.82882883 | L44: =IF(E44+H44='V2 Corrected'!B7+'V2 Corrected'!C8+'V2 Corrected'!D9+'V2 Corrected'!E10+'V2 Corrected'!F11+'V2 Corrected'!G12,"OK","MISMATCH") -> OK
A45: Haiku 4.5 | B45: v1 | C45: original | D45: 37 | E45: 8 | F45: 21 | G45: 113 | H45: 80 | I45: 9 | J45: =E45/D45 -> 0.21621622 | K45: =H45/G45 -> 0.7079646 | L45: =IF(E45+H45='V1 Matrices'!B18+'V1 Matrices'!C19+'V1 Matrices'!D20+'V1 Matrices'!E21+'V1 Matrices'!F22+'V1 Matrices'!G23,"OK","MISMATCH") -> OK
...

Sheet Disagreement Analysis
A1: Disagreement analysis — 24 listings all three v2 models got wrong
A2: Reviewed by hand on 9 Oct against original labels. Each row assigned one cause. Full worksheet: week-02/data/disagreements_v2.csv
A4: Cause | B4: Count | C4: Share | D4: What it means | E4: Fix it points to
A5: label error | B5: 13 | C5: =B5/$B$10 -> 0.54166667 | D5: My label was wrong; on re-reading, the models were right. | E5: Golden-set problem → correct the label
A6: rubric gap | B6: 6 | C6: =B6/$B$10 -> 0.25 | D6: No written rule decided the case; both answers were defensible. | E6: Spec problem → write a rule
A7: spec mismatch | B7: 5 | C7: =B7/$B$10 -> 0.20833333 | D7: A rule existed in my labeling instructions but the prompt lacked it or said the opposite. | E7: Prompt problem → align the prompt
A8: genuine ambiguity | B8: 0 | C8: =B8/$B$10 -> 0 | D8: The listing itself supports more than one tier. | E8: Data problem → better listings / photos
A9: model error | B9: 0 | C9: =B9/$B$10 -> 0 | D9: My label followed the rubric; the models misread it. | E9: Model problem
A10: Total | B10: =SUM(B5:B9) -> 24
A12: Model consensus as a signal
A13: Group | B13: Rows | C13: Label errors | D13: Share
A14: All three models agreed with each other | B14: 17 | C14: 10 | D14: =C14/B14 -> 0.58823529
A15: Models split among themselves | B15: 7 | C15: 3 | D15: =C15/B15 -> 0.42857143
A16: Counted directly from disagreements_v2.csv (final causes). Consensus rows were label errors 59% of the time vs 43% for split rows: a modest hint on 24 rows, not a strong signal. An earlier version reported 13 of 17 and 0 of 7 in error.
A18: Clusters found
A19: Cluster | B19: Rows | C19: Resolution
A20: Packaging/tags with no wear language | B20: L017, L034, L065, L067, L068, L070, L071 | C20: Box/dust bag not evidence; tags attached are evidence of unworn (rubric decides Pristine vs Excellent)
A21: Two conflicting condition statements | B21: L028, L030, L140, L142 | C21: New rule: no wear described → grade to the lower statement
A22: Good vs Fair contradiction in rubric | B22: L035, L039, L048 | C22: Fair = functional impairment, 3+ structural flaws, or stated need for repair
A23: Severity vs mark count | B23: L105 | C23: Visible staining = Good regardless of mark count
A24: My conservatism / missed details | B24: L037, L061, L083, L096, L108, L109, L123, L127, L082 | C24: Corrected as label errors
A26: Limit: only rows where all three models missed were reviewed. Rows where one model alone was wrong were not, and real model errors live there.

Sheet Label Amendments
A1: Label amendments — 9 Oct 2026 (29 rows)
A2: Every change is dated and explained in labels.csv (label_notes starts with 'AMENDED'). Original labels remain in git history and are the headline.
A4: Listing | B4: Category | C4: Before | D4: After | E4: Reason
A5: L017 | B5: shoes | C5: excellent | D5: insufficient information | E5: Packaging rule: box & dust bag aren't condition evidence
A6: L067 | B6: handbag | C6: excellent | D6: insufficient information | E6: Packaging rule
A7: L068 | B7: clothing | C7: insufficient information | D7: pristine | E7: Tags rule: tags attached on clothing = unworn
A8: L070 | B8: clothing | C8: insufficient information | D8: pristine | E8: Tags rule
A9: L071 | B9: clothing | C9: insufficient information | D9: pristine | E9: Tags rule
A10: L108 | B10: clothing | C10: excellent | D10: pristine | E10: Tags rule (never worn, tag attached)
A11: L109 | B11: clothing | C11: excellent | D11: pristine | E11: Tags rule (new with tags)
A12: L076 | B12: shoes | C12: excellent | D12: pristine | E12: Tags + box + dust bag
A13: L101 | B13: jewelry | C13: excellent | D13: pristine | E13: Tags, no wear; jewelry doesn't require tags
A14: L034 | B14: handbag | C14: insufficient information | D14: excellent | E14: Tags + dust bag, no box
A15: L065 | B15: handbag | C15: insufficient information | D15: excellent | E15: Tags + dust bag, no box
... A33: L035 | B33: handbag | C33: very good | D33: fair | E33: Review label error: sticky zipper = functional impairment

Sheet Rubric Changes
A1: Rules written or changed during Week 2
A3: Date | B3: Rule | C3: Why
A4: Labeling | B4: Label from title + description only; price, platform condition field, platform, photos hidden | C4: The model only sees title and description — same input or the comparison means nothing
A5: Labeling | B5: Bare claims are gradeable: take the claim, cap below Pristine, low confidence, tag 'claim without evidence' | C5: A seller's verdict is information, but not evidence
A6: Labeling | B6: Verdict vs fact: 'gently used', 'Pre-owned - Good' are verdicts; 'never worn', 'original packaging' are facts | C6: Boilerplate splits two ways
A7: Labeling | B7: Insufficient information only when there is no condition language at all | C7: Narrow, reproducible decline rule
A8: Labeling | B8: Contradictions: discard the title's claim, grade the description's evidence | C8: A stated flaw beats a title adjective
A9: Labeling | B9: Authentication flag dropped | C9: Authenticity can't be judged from text and there's no ground truth
A10: 2026-10-06 | B10: No brand named → 'Unbranded' | C10: Mostly fine jewelry sold on materials; matches how I'd already labeled
A11: 2026-10-09 | B11: Box and dust bag alone are not condition evidence (any category) | C11: Easily kept regardless of use
A12: 2026-10-09 | B12: Tags attached are evidence of unworn (any category); rubric packaging criteria decide the tier | C12: Tags come off when items are used
A13: 2026-10-09 | B13: What counts as tags; confidence by category (strong for clothing, weak elsewhere) | C13: Make the judgment reproducible
A14: 2026-10-09 | B14: Visible staining = Good regardless of mark count | C14: Severity overrides count
... A18: 2026-10-09 | B18: Rejected: '5 or more marks = Good' → 'more than 5' | C18: Proposed only to make one label right after seeing results

Sheet Predictions
A1: Pre-registered predictions vs results
A2: Each prediction was committed to NOTES.md before the data it predicts existed.
A4: Prediction | B4: What I predicted | C4: Result | D4: Status
A5: P1 — who writes the copy | B5: Staff-written listings agree ≥10 pts higher than seller-written | C5: Not run | D5: Untested
A6: P1b — evidence density | B6: Detailed listings agree more than sparse ones, by more than the P1 gap | C6: Not run | D6: Untested
A7: P2 — direction of skew | B7: Where models disagree, they grade more generously | C7: v1: Sonnet 27 vs 14, Haiku 19 vs 7, Opus 17 vs 14. v2: 20 vs 15, 19 vs 8, 13 vs 16 | D7: Held for Sonnet & Haiku; Opus balanced (v1) / slightly stricter (v2)
A8: P2 — worse on sparse listings | B8: Generous skew larger on sparse listings | C8: Not run | D8: Untested
A9: Packaging rule won't transfer | B9: Models will miss the category-specific Pristine rule | C9: Excellent→Pristine v1 8/9/4, v2 10/7/3 | D9: Held, especially Sonnet
A10: Experiment — tagged agreement | B10: Aligned prompt raises tagged-row agreement to ~60% | C10: 74/111 = 66.7% | D10: Held
A11: Experiment — largest gain | B11: Opus gains most | C11: Opus 6→28 of 37 | D11: Held
A12: Disagreement review | B12: No count was written down before the review | C12: 13 of 24 were my label errors | D12: Not pre-registered — reported as a finding, not a prediction

Sheet Findings
A1: Findings, in the order they were discovered
A3: # | B3: Finding | C3: Evidence | D3: Implication
A4: 1 | B4: Brand is reliable; subcategory is noise | C4: Brand ~91% every run. Subcategory 20–34%. | D4: Subcategory was unconstrained free text. Constrain it in Week 3.
A5: 2 | B5: Biggest v1 disagreement: models declining where I graded | C5: 29 / 30 / 38 declines = 38–51% of disagreements. | D5: Systematic, not random.
A6: 3 | B6: Spec mismatch: my rules contradicted my prompt | C6: 37 tagged rows = 25% of set, ~two-thirds of v1 declines; tagged agreement 16–22%. | D6: The models followed the prompt. Contradiction was in the prompt AND the tool description.
A7: 4 | B7: My Haiku hypothesis was wrong | C7: Haiku and Sonnet tied on tagged rows (8/37). | D7: Haiku's lead came from evidence-bearing rows.
A8: 5 | B8: Aligning the spec fixed it (pre-registered) | C8: Tagged 22→68%, 22→57%, 16→76%. | D8: Mismatch was the cause, not difficulty.
A9: 6 | B9: Regression test passed | C9: Untagged 58→71%, 71→78%, 62→75%; overall 49→70%, 59→73%, 51→75%. | D9: Old decline rule suppressed grades beyond the tagged rows.
A10: 7 | B10: The fix's cost: more grading where I declined | C10: Sonnet 6→9 (8 as Excellent), Haiku 6→8, Opus 5→6. | D10: v2 errs slightly toward overconfidence — the costlier mistake.
A11: 8 | B11: None of the 24 'all wrong' rows was a clean model error | C11: 13 label error, 6 rubric gap, 5 spec mismatch. | D11: Remaining disagreement was mostly me and my spec.
A12: 9 | B12: Model consensus is only a modest hint of label error | C12: 10 of 17 consensus rows were label errors vs 3 of 7 split rows (59% vs 43%). | D12: Too few rows to rely on. Re-check every disagreement, not just consensus ones.
A13: 10 | B13: Six of 24 hinged on the title | C13: L034, L065, L068, L070, L071 ("w/ Tags") and L123 ("Excellent Condition") put the deciding fact in the title, which I under-read. | D13: Read titles as evidence; check the labeling instructions say so.
A14: 11 | B14: Correcting labels added 8–17 points | C14: v2 corrected: Sonnet 82%, Haiku 81%, Opus 87%. | D14: Roughly half of v2's apparent disagreement was label noise. Corrected numbers flatter models.
A15: 12 | B15: Cost vs agreement | C15: Haiku within a few points of the top model. | D15: About a fifth of Opus's price. Don't rank models on 150 listings.

Sheet Caveats & Next
A1: Limits of these numbers, and what's next
A3: Type | B3: Item
A4: Caveat | B4: Single rater. Agreement means match with one person's rubric, which runs stricter than market labels.
A5: Caveat | B5: v2 was written after seeing v1 results on the same 150 listings. Guardrails held, but v2 numbers are optimistic until tested on unseen listings.
A6: Caveat | B6: Corrected labels were changed after seeing model output; corrected scores flatter the models (Opus most). Original labels stay the headline.
A7: Caveat | B7: v2 changed the prompt and tool description together; their separate effects can't be measured.
A8: Caveat | B8: One run per model per prompt. Large shifts are robust; gaps of a few listings between models are not.
A9: Caveat | B9: Only the 24 rows all three models missed were reviewed; single-model errors were not.
A10: Caveat | B10: Blind re-label: recognition wasn't recorded; intra-rater comparison against Week 1 grades not yet run.
A11: Next | B11: Week 3: v3 prompt aligned with packaging, tags, conflicting-statements and Fair rules — ideally generated from rubric.md so prompt and rubric can't drift.
A12: Next | B12: Week 3: run v3 on 5,000 unseen listings; rerun these 150 as the regression check.
A13: Next | B13: Fix retry logic: don't retry permanent errors (e.g. 400 out-of-credits).
A14: Optional | B14: Platform and evidence-density slices (P1, P1b); blind re-label vs Week 1 comparison.

Sheet V1 Matrices
A1: Condition tier confusion matrices — v1 prompt, original labels (150 listings)
A2: Rows = my label; columns = model. Green diagonal = agreement. Left of diagonal = model more generous; right = stricter.
A5: Sonnet 5 — v1 prompt, original labels
A6: You ↓ / Model → | B6: Pristine | C6: Excellent | D6: Very Good | E6: Good | F6: Fair | G6: Insufficient | H6: Row total
A7: Pristine | B7: 8 | C7: 2 | D7: 0 | E7: 0 | F7: 0 | G7: 0 | H7: =SUM(B7:G7) -> 10
A8: Excellent | B8: 8 | C8: 18 | D8: 2 | E8: 0 | F8: 0 | G8: 3 | H8: =SUM(B8:G8) -> 31
A9: Very Good | B9: 0 | C9: 11 | D9: 12 | E9: 5 | F9: 1 | G9: 10 | H9: =SUM(B9:G9) -> 39
A10: Good | B10: 0 | C10: 0 | D10: 4 | E10: 7 | F10: 4 | G10: 15 | H10: =SUM(B10:G10) -> 30
A11: Fair | B11: 0 | C11: 0 | D11: 2 | E11: 2 | F11: 2 | G11: 1 | H11: =SUM(B11:G11) -> 7
A12: Insufficient | B12: 2 | C12: 4 | D12: 0 | E12: 0 | F12: 0 | G12: 27 | H12: =SUM(B12:G12) -> 33
A13: Column total | B13: =SUM(B7:B12) -> 18 | C13: =SUM(C7:C12) -> 35 | D13: =SUM(D7:D12) -> 20 | E13: =SUM(E7:E12) -> 14 | F13: =SUM(F7:F12) -> 7 | G13: =SUM(G7:G12) -> 56 | H13: =SUM(H7:H12) -> 150
A14: Total check | B14: =IF(H13=150,"OK","CHECK") -> OK
A16: Haiku 4.5 — v1 prompt, original labels
A17: You ↓ / Model → | B17: Pristine | C17: Excellent | D17: Very Good | E17: Good | F17: Fair | G17: Insufficient | H17: Row total
A18: Pristine | B18: 9 | C18: 1 | D18: 0 | E18: 0 | F18: 0 | G18: 0 | H18: =SUM(B18:G18) -> 10
A19: Excellent | B19: 9 | C19: 16 | D19: 1 | E19: 0 | F19: 0 | G19: 5 | H19: =SUM(B19:G19) -> 31
A20: Very Good | B20: 0 | C20: 7 | D20: 18 | E20: 3 | F20: 0 | G20: 11 | H20: =SUM(B20:G20) -> 39
A21: Good | B21: 0 | C21: 0 | D21: 1 | E21: 13 | F21: 2 | G21: 14 | H21: =SUM(B21:G21) -> 30
A22: Fair | B22: 0 | C22: 0 | D22: 0 | E22: 2 | F22: 5 | G22: 0 | H22: =SUM(B22:G22) -> 7
A23: Insufficient | B23: 5 | C23: 1 | D23: 0 | E23: 0 | F23: 0 | G23: 27 | H23: =SUM(B23:G23) -> 33
A24: Column total | B24: =SUM(B18:B23) -> 23 | C24: =SUM(C18:C23) -> 25 | D24: =SUM(D18:D23) -> 20 | E24: =SUM(E18:E23) -> 18 | F24: =SUM(F18:F23) -> 7 | G24: =SUM(G18:G23) -> 57 | H24: =SUM(H18:H23) -> 150
A25: Total check | B25: =IF(H24=150,"OK","CHECK") -> OK
A27: Opus 5 — v1 prompt, original labels
A28: You ↓ / Model → | B28: Pristine | C28: Excellent | D28: Very Good | E28: Good | F28: Fair | G28: Insufficient | H28: Row total
A29: Pristine | B29: 9 | C29: 1 | D29: 0 | E29: 0 | F29: 0 | G29: 0 | H29: =SUM(B29:G29) -> 10
A30: Excellent | B30: 4 | C30: 19 | D30: 3 | E30: 0 | F30: 0 | G30: 5 | H30: =SUM(B30:G30) -> 31
A31: Very Good | B31: 0 | C31: 6 | D31: 11 | E31: 5 | F31: 1 | G31: 16 | H31: =SUM(B31:G31) -> 39
A32: Good | B32: 0 | C32: 0 | D32: 3 | E32: 7 | F32: 4 | G32: 16 | H32: =SUM(B32:G32) -> 30
A33: Fair | B33: 0 | C33: 0 | D33: 2 | E33: 2 | F33: 2 | G33: 1 | H33: =SUM(B33:G33) -> 7
A34: Insufficient | B34: 3 | C34: 2 | D34: 0 | E34: 0 | F34: 0 | G34: 28 | H34: =SUM(B34:G34) -> 33
A35: Column total | B35: =SUM(B29:B34) -> 16 | C35: =SUM(C29:C34) -> 28 | D35: =SUM(D29:D34) -> 19 | E35: =SUM(E29:E34) -> 14 | F35: =SUM(F29:F34) -> 7 | G35: =SUM(G29:G34) -> 66 | H35: =SUM(H29:H34) -> 150
A36: Total check | B36: =IF(H35=150,"OK","CHECK") -> OK

Sheet V2 Matrices
A1: Condition tier confusion matrices — v2 prompt, original labels (150 listings)
A2: Rows = my label; columns = model. Green diagonal = agreement. Left of diagonal = model more generous; right = stricter.
A5: Sonnet 5 — v2 prompt, original labels
A6: You ↓ / Model → | B6: Pristine | C6: Excellent | D6: Very Good | E6: Good | F6: Fair | G6: Insufficient | H6: Row total
A7: Pristine | B7: 9 | C7: 1 | D7: 0 | E7: 0 | F7: 0 | G7: 0 | H7: =SUM(B7:G7) -> 10
A8: Excellent | B8: 10 | C8: 18 | D8: 2 | E8: 0 | F8: 0 | G8: 1 | H8: =SUM(B8:G8) -> 31
A9: Very Good | B9: 0 | C9: 6 | D9: 25 | E9: 7 | F9: 1 | G9: 0 | H9: =SUM(B9:G9) -> 39
A10: Good | B10: 0 | C10: 0 | D10: 2 | E10: 24 | F10: 4 | G10: 0 | H10: =SUM(B10:G10) -> 30
A11: Fair | B11: 0 | C11: 0 | D11: 0 | E11: 2 | F11: 5 | G11: 0 | H11: =SUM(B11:G11) -> 7
A12: Insufficient | B12: 1 | C12: 8 | D12: 0 | E12: 0 | F12: 0 | G12: 24 | H12: =SUM(B12:G12) -> 33
A13: Column total | B13: =SUM(B7:B12) -> 20 | C13: =SUM(C7:C12) -> 33 | D13: =SUM(D7:D12) -> 29 | E13: =SUM(E7:E12) -> 33 | F13: =SUM(F7:F12) -> 10 | G13: =SUM(G7:G12) -> 25 | H13: =SUM(H7:H12) -> 150
A14: Total check | B14: =IF(H13=150,"OK","CHECK") -> OK
A16: Haiku 4.5 — v2 prompt, original labels
A17: You ↓ / Model → | B17: Pristine | C17: Excellent | D17: Very Good | E17: Good | F17: Fair | G17: Insufficient | H17: Row total
A18: Pristine | B18: 10 | C18: 0 | D18: 0 | E18: 0 | F18: 0 | G18: 0 | H18: =SUM(B18:G18) -> 10
A19: Excellent | B19: 7 | C19: 23 | D19: 0 | E19: 0 | F19: 0 | G19: 1 | H19: =SUM(B19:G19) -> 31
A20: Very Good | B20: 0 | C20: 8 | D20: 23 | E20: 6 | F20: 0 | G20: 2 | H20: =SUM(B20:G20) -> 39
A21: Good | B21: 0 | C21: 0 | D21: 2 | E21: 23 | F21: 2 | G21: 3 | H21: =SUM(B21:G21) -> 30
A22: Fair | B22: 0 | C22: 0 | D22: 0 | E22: 2 | F22: 5 | G22: 0 | H22: =SUM(B22:G22) -> 7
A23: Insufficient | B23: 6 | C23: 2 | D23: 0 | E23: 0 | F23: 0 | G23: 25 | H23: =SUM(B23:G23) -> 33
A24: Column total | B24: =SUM(B18:B23) -> 23 | C24: =SUM(C18:C23) -> 33 | D24: =SUM(D18:D23) -> 25 | E24: =SUM(E18:E23) -> 31 | F24: =SUM(F18:F23) -> 7 | G24: =SUM(G18:G23) -> 31 | H24: =SUM(H18:H23) -> 150
A25: Total check | B25: =IF(H24=150,"OK","CHECK") -> OK
A27: Opus 5 — v2 prompt, original labels
A28: You ↓ / Model → | B28: Pristine | C28: Excellent | D28: Very Good | E28: Good | F28: Fair | G28: Insufficient | H28: Row total
A29: Pristine | B29: 9 | C29: 1 | D29: 0 | E29: 0 | F29: 0 | G29: 0 | H29: =SUM(B29:G29) -> 10
A30: Excellent | B30: 3 | C30: 22 | D30: 4 | E30: 0 | F30: 0 | G30: 2 | H30: =SUM(B30:G30) -> 31
A31: Very Good | B31: 0 | C31: 6 | D31: 26 | E31: 5 | F31: 2 | G31: 0 | H31: =SUM(B31:G31) -> 39
A32: Good | B32: 0 | C32: 0 | D32: 4 | E32: 22 | F32: 4 | G32: 0 | H32: =SUM(B32:G32) -> 30
A33: Fair | B33: 0 | C33: 0 | D33: 0 | E33: 0 | F33: 7 | G33: 0 | H33: =SUM(B33:G33) -> 7
A34: Insufficient | B34: 3 | C34: 3 | D34: 0 | E34: 0 | F34: 0 | G34: 27 | H34: =SUM(B34:G34) -> 33
A35: Column total | B35: =SUM(B29:B34) -> 15 | C35: =SUM(C29:C34) -> 32 | D35: =SUM(D29:D34) -> 34 | E35: =SUM(E29:E34) -> 27 | F35: =SUM(F29:F34) -> 13 | G35: =SUM(G29:G34) -> 29 | H35: =SUM(H29:H34) -> 150
A36: Total check | B36: =IF(H35=150,"OK","CHECK") -> OK

Sheet V1 Corrected
A1: Condition tier confusion matrices — v1 prompt, corrected labels (150 listings)
A2: Rows = my label; columns = model. Green diagonal = agreement. Left of diagonal = model more generous; right = stricter.
A3: Corrected labels = after the 9 Oct disagreement review and rubric amendments (29 rows changed). Changes were informed by model output, so these numbers flatter the models.
A5: Sonnet 5 — v1 prompt, corrected labels
A6: You ↓ / Model → | B6: Pristine | C6: Excellent | D6: Very Good | E6: Good | F6: Fair | G6: Insufficient | H6: Row total
A7: Pristine | B7: 12 | C7: 4 | D7: 0 | E7: 0 | F7: 0 | G7: 0 | H7: =SUM(B7:G7) -> 16
A8: Excellent | B8: 4 | C8: 21 | D8: 2 | E8: 0 | F8: 0 | G8: 4 | H8: =SUM(B8:G8) -> 31
A9: Very Good | B9: 0 | C9: 8 | D9: 11 | E9: 2 | F9: 0 | G9: 7 | H9: =SUM(B9:G9) -> 28
A10: Good | B10: 0 | C10: 2 | D10: 5 | E10: 10 | F10: 2 | G10: 17 | H10: =SUM(B10:G10) -> 36
A11: Fair | B11: 0 | C11: 0 | D11: 2 | E11: 2 | F11: 5 | G11: 1 | H11: =SUM(B11:G11) -> 10
A12: Insufficient | B12: 2 | C12: 0 | D12: 0 | E12: 0 | F12: 0 | G12: 27 | H12: =SUM(B12:G12) -> 29
A13: Column total | B13: =SUM(B7:B12) -> 18 | C13: =SUM(C7:C12) -> 35 | D13: =SUM(D7:D12) -> 20 | E13: =SUM(E7:E12) -> 14 | F13: =SUM(F7:F12) -> 7 | G13: =SUM(G7:G12) -> 56 | H13: =SUM(H7:H12) -> 150
A14: Total check | B14: =IF(H13=150,"OK","CHECK") -> OK
A16: Haiku 4.5 — v1 prompt, corrected labels
A17: You ↓ / Model → | B17: Pristine | C17: Excellent | D17: Very Good | E17: Good | F17: Fair | G17: Insufficient | H17: Row total
A18: Pristine | B18: 15 | C18: 1 | D18: 0 | E18: 0 | F18: 0 | G18: 0 | H18: =SUM(B18:G18) -> 16
A19: Excellent | B19: 8 | C19: 17 | D19: 1 | E19: 0 | F19: 0 | G19: 5 | H19: =SUM(B19:G19) -> 31
A20: Very Good | B20: 0 | C20: 4 | D20: 16 | E20: 0 | F20: 0 | G20: 8 | H20: =SUM(B20:G20) -> 28
A21: Good | B21: 0 | C21: 2 | D21: 3 | E21: 15 | F21: 0 | G21: 16 | H21: =SUM(B21:G21) -> 36
A22: Fair | B22: 0 | C22: 0 | D22: 0 | E22: 3 | F22: 7 | G22: 0 | H22: =SUM(B22:G22) -> 10
A23: Insufficient | B23: 0 | C23: 1 | D23: 0 | E23: 0 | F23: 0 | G23: 28 | H23: =SUM(B23:G23) -> 29
A24: Column total | B24: =SUM(B18:B23) -> 23 | C24: =SUM(C18:C23) -> 25 | D24: =SUM(D18:D23) -> 20 | E24: =SUM(E18:E23) -> 18 | F24: =SUM(F18:F23) -> 7 | G24: =SUM(G18:G23) -> 57 | H24: =SUM(H18:H23) -> 150
A25: Total check | B25: =IF(H24=150,"OK","CHECK") -> OK
A27: Opus 5 — v1 prompt, corrected labels
A28: You ↓ / Model → | B28: Pristine | C28: Excellent | D28: Very Good | E28: Good | F28: Fair | G28: Insufficient | H28: Row total
A29: Pristine | B29: 16 | C29: 0 | D29: 0 | E29: 0 | F29: 0 | G29: 0 | H29: =SUM(B29:G29) -> 16
A30: Excellent | B30: 0 | C30: 23 | D30: 3 | E30: 0 | F30: 0 | G30: 5 | H30: =SUM(B30:G30) -> 31
A31: Very Good | B31: 0 | C31: 3 | D31: 10 | E31: 2 | F31: 0 | G31: 13 | H31: =SUM(B31:G31) -> 28
A32: Good | B32: 0 | C32: 2 | D32: 4 | E32: 10 | F32: 2 | G32: 18 | H32: =SUM(B32:G32) -> 36
A33: Fair | B33: 0 | C33: 0 | D33: 2 | E33: 2 | F33: 5 | G33: 1 | H33: =SUM(B33:G33) -> 10
A34: Insufficient | B34: 0 | C34: 0 | D34: 0 | E34: 0 | F34: 0 | G34: 29 | H34: =SUM(B34:G34) -> 29
A35: Column total | B35: =SUM(B29:B34) -> 16 | C35: =SUM(C29:C34) -> 28 | D35: =SUM(D29:D34) -> 19 | E35: =SUM(E29:E34) -> 14 | F35: =SUM(F29:F34) -> 7 | G35: =SUM(G29:G34) -> 66 | H35: =SUM(H29:H34) -> 150
A36: Total check | B36: =IF(H35=150,"OK","CHECK") -> OK

Sheet V2 Corrected
A1: Condition tier confusion matrices — v2 prompt, corrected labels (150 listings)
A2: Rows = my label; columns = model. Green diagonal = agreement. Left of diagonal = model more generous; right = stricter.
A3: Corrected labels = after the 9 Oct disagreement review and rubric amendments (29 rows changed). Changes were informed by model output, so these numbers flatter the models.
A5: Sonnet 5 — v2 prompt, corrected labels
A6: You ↓ / Model → | B6: Pristine | C6: Excellent | D6: Very Good | E6: Good | F6: Fair | G6: Insufficient | H6: Row total
A7: Pristine | B7: 14 | C7: 2 | D7: 0 | E7: 0 | F7: 0 | G7: 0 | H7: =SUM(B7:G7) -> 16
A8: Excellent | B8: 5 | C8: 24 | D8: 2 | E8: 0 | F8: 0 | G8: 0 | H8: =SUM(B8:G8) -> 31
A9: Very Good | B9: 0 | C9: 3 | D9: 23 | E9: 2 | F9: 0 | G9: 0 | H9: =SUM(B9:G9) -> 28
A10: Good | B10: 0 | C10: 1 | D10: 4 | E10: 29 | F10: 2 | G10: 0 | H10: =SUM(B10:G10) -> 36
A11: Fair | B11: 0 | C11: 0 | D11: 0 | E11: 2 | F11: 8 | G11: 0 | H11: =SUM(B11:G11) -> 10
A12: Insufficient | B12: 1 | C12: 3 | D12: 0 | E12: 0 | F12: 0 | G12: 25 | H12: =SUM(B12:G12) -> 29
A13: Column total | B13: =SUM(B7:B12) -> 20 | C13: =SUM(C7:C12) -> 33 | D13: =SUM(D7:D12) -> 29 | E13: =SUM(E7:E12) -> 33 | F13: =SUM(F7:F12) -> 10 | G13: =SUM(G7:G12) -> 25 | H13: =SUM(H7:H12) -> 150
A14: Total check | B14: =IF(H13=150,"OK","CHECK") -> OK
A16: Haiku 4.5 — v2 prompt, corrected labels
A17: You ↓ / Model → | B17: Pristine | C17: Excellent | D17: Very Good | E17: Good | F17: Fair | G17: Insufficient | H17: Row total
A18: Pristine | B18: 14 | C18: 2 | D18: 0 | E18: 0 | F18: 0 | G18: 0 | H18: =SUM(B18:G18) -> 16
A19: Excellent | B19: 6 | C19: 25 | D19: 0 | E19: 0 | F19: 0 | G19: 0 | H19: =SUM(B19:G19) -> 31
A20: Very Good | B20: 0 | C20: 4 | D20: 22 | E20: 0 | F20: 0 | G20: 2 | H20: =SUM(B20:G20) -> 28
A21: Good | B21: 0 | C21: 2 | D21: 3 | E21: 28 | F21: 0 | G21: 3 | H21: =SUM(B21:G21) -> 36
A22: Fair | B22: 0 | C22: 0 | D22: 0 | E22: 3 | F22: 7 | G22: 0 | H22: =SUM(B22:G22) -> 10
A23: Insufficient | B23: 3 | C23: 0 | D23: 0 | E23: 0 | F23: 0 | G23: 26 | H23: =SUM(B23:G23) -> 29
A24: Column total | B24: =SUM(B18:B23) -> 23 | C24: =SUM(C18:C23) -> 33 | D24: =SUM(D18:D23) -> 25 | E24: =SUM(E18:E23) -> 31 | F24: =SUM(F18:F23) -> 7 | G24: =SUM(G18:G23) -> 31 | H24: =SUM(H18:H23) -> 150
A25: Total check | B25: =IF(H24=150,"OK","CHECK") -> OK
A27: Opus 5 — v2 prompt, corrected labels
A28: You ↓ / Model → | B28: Pristine | C28: Excellent | D28: Very Good | E28: Good | F28: Fair | G28: Insufficient | H28: Row total
A29: Pristine | B29: 15 | C29: 1 | D29: 0 | E29: 0 | F29: 0 | G29: 0 | H29: =SUM(B29:G29) -> 16
A30: Excellent | B30: 0 | C30: 27 | D30: 4 | E30: 0 | F30: 0 | G30: 0 | H30: =SUM(B30:G30) -> 31
A31: Very Good | B31: 0 | C31: 2 | D31: 24 | E31: 2 | F31: 0 | G31: 0 | H31: =SUM(B31:G31) -> 28
A32: Good | B32: 0 | C32: 2 | D32: 6 | E32: 25 | F32: 3 | G32: 0 | H32: =SUM(B32:G32) -> 36
A33: Fair | B33: 0 | C33: 0 | D33: 0 | E33: 0 | F33: 10 | G33: 0 | H33: =SUM(B33:G33) -> 10
A34: Insufficient | B34: 0 | C34: 0 | D34: 0 | E34: 0 | F34: 0 | G34: 29 | H34: =SUM(B34:G34) -> 29
A35: Column total | B35: =SUM(B29:B34) -> 15 | C35: =SUM(C29:C34) -> 32 | D35: =SUM(D29:D34) -> 34 | E35: =SUM(E29:E34) -> 27 | F35: =SUM(F29:F34) -> 13 | G35: =SUM(G29:G34) -> 29 | H35: =SUM(H29:H34) -> 150
A36: Total check | B36: =IF(H35=150,"OK","CHECK") -> OK

Sheet V2 Tagged Matrices
A1: v2 experiment — the 37 'claim without evidence' rows only (original labels)
A4: Sonnet 5 — v2, tagged 37
A5: You ↓ / Model → | B5: Pristine | C5: Excellent | D5: Very Good | E5: Good | F5: Fair | G5: Insufficient | H5: Row total
A6: Pristine | B6: 2 | C6: 1 | D6: 0 | E6: 0 | F6: 0 | G6: 0 | H6: =SUM(B6:G6) -> 3
A7: Excellent | B7: 5 | C7: 2 | D7: 0 | E7: 0 | F7: 0 | G7: 0 | H7: =SUM(B7:G7) -> 7
A8: Very Good | B8: 0 | C8: 3 | D8: 12 | E8: 1 | F8: 1 | G8: 0 | H8: =SUM(B8:G8) -> 17
A9: Good | B9: 0 | C9: 0 | D9: 1 | E9: 8 | F9: 0 | G9: 0 | H9: =SUM(B9:G9) -> 9
A10: Fair | B10: 0 | C10: 0 | D10: 0 | E10: 0 | F10: 1 | G10: 0 | H10: =SUM(B10:G10) -> 1
A11: Insufficient | B11: 0 | C11: 0 | D11: 0 | E11: 0 | F11: 0 | G11: 0 | H11: =SUM(B11:G11) -> 0
A12: Column total | B12: =SUM(B6:B11) -> 7 | C12: =SUM(C6:C11) -> 6 | D12: =SUM(D6:D11) -> 13 | E12: =SUM(E6:E11) -> 9 | F12: =SUM(F6:F11) -> 2 | G12: =SUM(G6:G11) -> 0 | H12: =SUM(H6:H11) -> 37
A13: Total check | B13: =IF(H12=37,"OK","CHECK") -> OK
A15: Haiku 4.5 — v2, tagged 37
A16: You ↓ / Model → | B16: Pristine | C16: Excellent | D16: Very Good | E16: Good | F16: Fair | G16: Insufficient | H16: Row total
A17: Pristine | B17: 3 | C17: 0 | D17: 0 | E17: 0 | F17: 0 | G17: 0 | H17: =SUM(B17:G17) -> 3
A18: Excellent | B18: 4 | C18: 3 | D18: 0 | E18: 0 | F18: 0 | G18: 0 | H18: =SUM(B18:G18) -> 7
A19: Very Good | B19: 0 | C19: 4 | D19: 9 | E19: 2 | F19: 0 | G19: 2 | H19: =SUM(B19:G19) -> 17
A20: Good | B20: 0 | C20: 0 | D20: 1 | E20: 5 | F20: 0 | G20: 3 | H20: =SUM(B20:G20) -> 9
A21: Fair | B21: 0 | C21: 0 | D21: 0 | E21: 0 | F21: 1 | G21: 0 | H21: =SUM(B21:G21) -> 1
A22: Insufficient | B22: 0 | C22: 0 | D22: 0 | E22: 0 | F22: 0 | G22: 0 | H22: =SUM(B22:G22) -> 0
A23: Column total | B23: =SUM(B17:B22) -> 7 | C23: =SUM(C17:C22) -> 7 | D23: =SUM(D17:D22) -> 10 | E23: =SUM(E17:E22) -> 7 | F23: =SUM(F17:F22) -> 1 | G23: =SUM(G17:G22) -> 5 | H23: =SUM(H17:H22) -> 37
A24: Total check | B24: =IF(H23=37,"OK","CHECK") -> OK
A26: Opus 5 — v2, tagged 37
A27: You ↓ / Model → | B27: Pristine | C27: Excellent | D27: Very Good | E27: Good | F27: Fair | G27: Insufficient | H27: Row total
A28: Pristine | B28: 2 | C28: 1 | D28: 0 | E28: 0 | F28: 0 | G28: 0 | H28: =SUM(B28:G28) -> 3
A29: Excellent | B29: 1 | C29: 5 | D29: 0 | E29: 0 | F29: 0 | G29: 1 | H29: =SUM(B29:G29) -> 7
A30: Very Good | B30: 0 | C30: 4 | D30: 12 | E30: 0 | F30: 1 | G30: 0 | H30: =SUM(B30:G30) -> 17
A31: Good | B31: 0 | C31: 0 | D31: 1 | E31: 8 | F31: 0 | G31: 0 | H31: =SUM(B31:G31) -> 9
A32: Fair | B32: 0 | C32: 0 | D32: 0 | E32: 0 | F32: 1 | G32: 0 | H32: =SUM(B32:G32) -> 1
A33: Insufficient | B33: 0 | C33: 0 | D33: 0 | E33: 0 | F33: 0 | G33: 0 | H33: =SUM(B33:G33) -> 0
A34: Column total | B34: =SUM(B28:B33) -> 3 | C34: =SUM(C28:C33) -> 10 | D34: =SUM(D28:D33) -> 13 | E34: =SUM(E28:E33) -> 8 | F34: =SUM(F28:F33) -> 2 | G34: =SUM(G28:G33) -> 1 | H34: =SUM(H28:H33) -> 37
A35: Total check | B35: =IF(H34=37,"OK","CHECK") -> OK

Sheet Week 1 Baseline
A1: Week 1 baseline (Sonnet 5, 30 listings, original prompt)
A3: Measure | B3: Matches | C3: Denominator | D3: Agreement
A4: All graded listings | B4: 8 | C4: 30 | D4: =B4/C4 -> 0.26666667
A5: Both assigned a real tier | B5: 8 | C5: 20 | D5: =B5/C5 -> 0.4
A7: Not like-for-like: Week 2 adds the full rubric to the prompt, cleaner labels, and 150 listings instead of 30.
